Workbook
Name _A65600: #REF!
Name _A66000: #REF!
Name _A67000: #REF!
Name a: #REF!
Name aaff: #REF!
Name aff: #REF!
Name afff: #REF!
Name AGOSTO: #REF!
Name AGOSTO1: #REF!
Name Aguascalientes: #REF!
Name BC: #REF!
Name BCS: #REF!
Name Campeche: #REF!
Name Categorías_de_gastos: #REF!
Name CDMX: #REF!
Name ceroo: #REF!
Name Chiapas: #REF!
Name Chihuahua: #REF!
Name CK: #REF!
Name Coahuila: #REF!
Name Colima: #REF!
Name ControlConfianza: #REF!
Name Database: #REF!
Name datosum: '[1]2015 ESTRUCTURA'!$N$56:$N$3552
Name Durango: #REF!
Name e: #REF!
Name Edos: #REF!
Name EducationLevel: #REF!
Name EnglishAbility: #REF!
Name Est: #REF!
Name Estado: #REF!
Name Estados: #REF!
Name FEB: #REF!
Name FF: #REF!
Name FFFF: #REF!
Name Gender: #REF!
Name Genero: #REF!
Name Guanajuato: #REF!
Name Guerrero: #REF!
Name Hidalgo: #REF!
Name Jalisco: #REF!
Name MAYO: #REF!
Name México: #REF!
Name Michoacán: #REF!
Name MiColumna: '[2]24 San Luis Potosi'!#REF!
Name MiFila: '[2]24 San Luis Potosi'!#REF!
Name Morelos: #REF!
Name Nayarit: #REF!
Name NL: #REF!
Name Oaxaca: #REF!
Name ParticipantAlternate: #REF!
Name PERIODO: #REF!
Name POLICÍA_PREVENTIVO_ESTATAL: #REF!
Name PP: #REF!
Name Puebla: #REF!
Name Qroo: #REF!
Name Querétaro: #REF!
Name Reintegra: #REF!
Name Reintegros: '[2]24 San Luis Potosi'!#REF!
Name Reintegros3: #REF!

Sheet RESUMEN PROG-SUBP VF FORTAMUN
B1: FONDO DE APORTACIONES PARA EL FORTALECIMIENTO DE LOS MUNICIPIOS Y DE LAS DEMARCACIONES TERRITORIALES DEL DISTRITO FEDERAL
B2: ESTRUCTURA PROGRAMÁTICA PRESUPUESTAL FORTAMUN 2026
B3: (RESUMEN)
B4: ENTIDAD FEDERATIVA: PUEBLA
B5: MUNICIPIO: CUETZALAN DEL PROGRESO
B6: (DIEZ MILLONES TRESCIENTOS SETENTA Y UN MIL DOSCIENTOS CINCUENTA Y TRES PESOS 70/100 M.N.)
B7: AÑO | C7: ENTIDAD | D7: MUNICIPIO | E7: EJE | F7: PROGRAMA | G7: SUBPROGRAMA | H7: PROGRAMAS CON PRIORIDAD NACIONAL Y SUBPROGRAMAS | I7: ORIGEN DE LOS RECURSOS
I8: APORTACIONES FEDERALES (FORTAMUN)
H9: TOTAL | I9: =+I10+I20+I24 -> 10371254 | L9: 10371254
B10: 2026 | C10: 21 | D10: 43 | E10: 1 | H10: =+'EPP FORTAMUN 26'!L10 -> Desarrollo de las y los integrantes de las Instituciones de Seguridad Pública | I10: =+'EPP FORTAMUN 26'!M10 -> 101625
B11: 2026 | C11: 21 | D11: 43 | E11: 1 | F11: 1 | H11: =+'EPP FORTAMUN 26'!L11 -> Fortalecimiento de las Instancias de Profesionalización y Formación de las y los integrantes de las Instituciones de Seguridad Pública | I11: =+'EPP FORTAMUN 26'!M11 -> 101625
B12: 2026 | C12: 21 | D12: 43 | E12: 1 | F12: 1 | G12: 1 | H12: =+'EPP FORTAMUN 26'!L12 -> Programas de Formación Inicial y Continua conforme al Programa Rector | I12: =+'EPP FORTAMUN 26'!M12 -> 101625
B13: 2026 | C13: 21 | D13: 43 | E13: 1 | F13: 1 | G13: 2 | H13: =+'EPP FORTAMUN 26'!L24 -> Equipamiento de las Instancias de Profesionalización de las Instituciones Policiales | I13: =+'EPP FORTAMUN 26'!M24 -> 0
B14: 2026 | C14: 21 | D14: 43 | E14: 1 | F14: 1 | G14: 3 | H14: =+'EPP FORTAMUN 26'!L288 -> Infraestructura de las Instancias de Profesionalización de las Instituciones Policiales | I14: =+'EPP FORTAMUN 26'!M288 -> 0
B15: 2026 | C15: 21 | D15: 43 | E15: 1 | F15: 2 | H15: =+'EPP FORTAMUN 26'!L294 -> Servicio Profesional de Carrera | I15: =+'EPP FORTAMUN 26'!M294 -> 0
B16: 2026 | C16: 21 | D16: 43 | E16: 1 | F16: 2 | G16: 6 | H16: =+'EPP FORTAMUN 26'!L295 -> Incremento del Estado de Fuerza de las Instituciones Policiales | I16: =+'EPP FORTAMUN 26'!M295 -> 0
B17: 2026 | C17: 21 | D17: 43 | E17: 1 | F17: 2 | G17: 8 | H17: =+'EPP FORTAMUN 26'!L300 -> Evaluaciones de Control de Confianza para las y los Integrantes de las Instituciones de Seguridad Pública | I17: =+'EPP FORTAMUN 26'!M300 -> 0
B18: 2026 | C18: 21 | D18: 43 | E18: 1 | F18: 2 | G18: 10 | H18: =+'EPP FORTAMUN 26'!L305 -> Mejora Salarial, Incentivos y Reconocimientos para las y los Integrantes de las Instituciones de Seguridad Pública | I18: =+'EPP FORTAMUN 26'!M305 -> 0
B19: 2026 | C19: 21 | D19: 43 | E19: 1 | F19: 2 | G19: 11 | H19: =+'EPP FORTAMUN 26'!L316 -> Seguridad Social y Prestaciones para las y los integrantes de las Instituciones de Seguridad Pública | I19: =+'EPP FORTAMUN 26'!M316 -> 0
B20: 2026 | C20: 21 | D20: 43 | E20: 2 | H20: =+'EPP FORTAMUN 26'!L325 -> Desarrollo de las Capacidades de las Instituciones de Seguridad Pública | I20: =+'EPP FORTAMUN 26'!M325 -> 1382053.7
B21: 2026 | C21: 21 | D21: 43 | E21: 2 | F21: 3 | H21: =+'EPP FORTAMUN 26'!L326 -> Fortalecimiento de las Instituciones Policiales | I21: =+'EPP FORTAMUN 26'!M326 -> 1382053.7
B22: 2026 | C22: 21 | D22: 43 | E22: 2 | F22: 3 | G22: 12 | H22: =+'EPP FORTAMUN 26'!L327 -> Equipamiento de las Instituciones Policiales | I22: =+'EPP FORTAMUN 26'!M327 -> 1382053.7
B23: 2026 | C23: 21 | D23: 43 | E23: 2 | F23: 3 | G23: 13 | H23: =+'EPP FORTAMUN 26'!L528 -> Infraestructura de las Instituciones Policiales | I23: =+'EPP FORTAMUN 26'!M528 -> 0
B24: 2026 | C24: 21 | D24: 43 | E24: 3 | H24: =+'EPP FORTAMUN 26'!L534 -> Modernización y Estandarización de la Infraestructura Tecnológica para la Seguridad Pública | I24: =+'EPP FORTAMUN 26'!M534 -> 8887575
B25: 2026 | C25: 21 | D25: 43 | E25: 3 | F25: 8 | H25: =+'EPP FORTAMUN 26'!L535 -> Fortalecimiento Tecnológico y Operativo de los Centros de Comando y Control y las Instituciones de Seguridad Pública | I25: =+'EPP FORTAMUN 26'!M535 -> 8846375
B26: 2026 | C26: 21 | D26: 43 | E26: 3 | F26: 8 | G26: 23 | H26: =+'EPP FORTAMUN 26'!L536 -> Actualización, Modernización y Mantenimiento de la Red Nacional de Radiocomunicación | I26: =+'EPP FORTAMUN 26'!M536 -> 680750
B27: 2026 | C27: 21 | D27: 43 | E27: 3 | F27: 8 | G27: 24 | H27: =+'EPP FORTAMUN 26'!L544 -> Sistemas de Identificación Vehicular y Videovigilancia Urbana para la Seguridad Pública | I27: =+'EPP FORTAMUN 26'!M544 -> 8165625
B28: 2026 | C28: 21 | D28: 43 | E28: 3 | F28: 9 | H28: =+'EPP FORTAMUN 26'!L584 -> Modernización de las Instancias Estatales del Registro Público Vehicular (REPUVE) | I28: =+'EPP FORTAMUN 26'!M584 -> 41200
B29: =+'EPP FORTAMUN 26'!B585 -> 2026 | C29: 21 | D29: 43 | E29: 3 | F29: 9 | G29: 26 | H29: =+'EPP FORTAMUN 26'!L585 -> Fortalecimiento de la Infraestructura de los Puntos de Monitoreo Vehicular (RFID+LPR) | I29: =+'EPP FORTAMUN 26'!M585 -> 41200
H42: LIC. OSCAR PAULA CRUZ
H43: PRESIDENTE MUNICIPAL CONSTITUCIONAL

Sheet EPP FORTAMUN 26
B1: FONDO DE APORTACIONES PARA EL FORTALECIMIENTO DE LOS MUNICIPIOS Y DE LAS DEMARCACIONES TERRITORIALES DEL DISTRITO FEDERAL
B2: ESTRUCTURA PROGRAMÁTICA PRESUPUESTAL FORTAMUN 2026
B3: ENTIDAD FEDERATIVA: PUEBLA
B4: MUNICIPIO: CUETZALAN DEL PROGRESO
B5: (DIEZ MILLONES TRESCIENTOS SETENTA Y UN MIL DOSCIENTOS CINCUENTA Y TRES PESOS 70/100 M.N.)
B7: AÑO | C7: ENTIDAD | D7: MUNICIPIO | E7: EJE | F7: PROGRAMA | G7: SUBPROGRAMA | H7: CAPÍTULO | I7: CONCEPTO | J7: PARTIDA GENÉRICA | K7: BIEN | L7: PROGRAMAS CON PRIORIDAD NACIONAL Y SUBPROGRAMAS | M7: ORIGEN DE LOS RECURSOS | N7: UNIDAD DE MEDIDA | O7: CANTIDAD | P7: PERSONA / CANTIDAD 2
M8: APORTACIONES FEDERALES (FORTAMUN)
L9: TOTAL | M9: =+M10+M325+M534 -> 10371254
B10: 2026 | C10: 21 | D10: 43 | E10: 1 | L10: Desarrollo de las y los integrantes de las Instituciones de Seguridad Pública | M10: =+M11+M294 -> 101625
B11: 2026 | C11: 21 | D11: 43 | E11: 1 | F11: 1 | L11: Fortalecimiento de las Instancias de Profesionalización y Formación de las y los integrantes de las Instituciones de Seguridad Pública | M11: =M12+M24+M288 -> 101625
B12: 2026 | C12: 21 | D12: 43 | E12: 1 | F12: 1 | G12: 1 | L12: Programas de Formación Inicial y Continua conforme al Programa Rector | M12: =+M13 -> 101625
B13: 2026 | C13: 21 | D13: 43 | E13: 1 | F13: 1 | G13: 1 | H13: 3000 | L13: Servicios Generales | M13: =+M14 -> 101625
B14: 2026 | C14: 21 | D14: 43 | E14: 1 | F14: 1 | G14: 1 | H14: 3000 | I14: 3300 | L14: Servicios Profesionales, Científicos, Técnicos y Otros Servicios | M14: =+M15+M19+M21 -> 101625
B15: 2026 | C15: 21 | D15: 43 | E15: 1 | F15: 1 | G15: 1 | H15: 3000 | I15: 3300 | J15: 334 | L15: Servicios de capacitación | M15: =SUM(M16:M18) -> 101625
B16: 2026 | C16: 21 | D16: 43 | E16: 1 | F16: 1 | G16: 1 | H16: 3000 | I16: 3300 | J16: 334 | K16: 460 | L16: Curso de capacitación para Policía Municipal_Formación Inicial (Aspirantes) | M16: 101625 | N16: Servicio | O16: 1
B17: 2026 | C17: 21 | D17: 43 | E17: 1 | F17: 1 | G17: 1 | H17: 3000 | I17: 3300 | J17: 334 | K17: 459 | L17: Curso de capacitación para Policía Municipal_Formación Inicial (Activos) | N17: Servicio
B18: 2026 | C18: 21 | D18: 43 | E18: 1 | F18: 1 | G18: 1 | H18: 3000 | I18: 3300 | J18: 334 | K18: 457 | L18: Curso de capacitación para Policía Municipal_Formación Continua | N18: Servicio
B19: 2026 | C19: 21 | D19: 43 | E19: 1 | F19: 1 | G19: 1 | H19: 3000 | I19: 3300 | J19: 336 | L19: Servicios de apoyo administrativo, traducción, fotocopiado e impresión | M19: =SUM(M20:M20) -> 0
B20: 2026 | C20: 21 | D20: 43 | E20: 1 | F20: 1 | G20: 1 | H20: 3000 | I20: 3300 | J20: 336 | K20: 660 | L20: Evaluación del desempeño para Policías Municipales | N20: Evaluación
B21: 2026 | C21: 21 | D21: 43 | E21: 1 | F21: 1 | G21: 1 | H21: 3000 | I21: 3300 | J21: 339 | L21: Servicios profesionales, científicos y técnicos integrales | M21: =SUM(M22:M23) -> 0
B22: 2026 | C22: 21 | D22: 43 | E22: 1 | F22: 1 | G22: 1 | H22: 3000 | I22: 3300 | J22: 339 | K22: 1404 | L22: Subcontratación de servicios con terceros_Evaluación de Competencias Básicas de la Función para Policías Municipales | N22: Evaluación
B23: 2026 | C23: 21 | D23: 43 | E23: 1 | F23: 1 | G23: 1 | H23: 3000 | I23: 3300 | J23: 339 | K23: 1400 | L23: Subcontratación de servicios con terceros_Evaluación de Aspirantes a Instructores Evaluadores de la Función Municipal | N23: Evaluación
B24: 2026 | C24: 21 | D24: 43 | E24: 1 | F24: 1 | G24: 2 | L24: Equipamiento de las Instancias de Profesionalización de las Instituciones Policiales | M24: =+M25+M133+M145 -> 0
B25: 2026 | C25: 21 | D25: 43 | E25: 1 | F25: 1 | G25: 2 | H25: 2000 | L25: Materiales y Suministros | M25: =+M26+M37+M40+M77 -> 0
B26: 2026 | C26: 21 | D26: 43 | E26: 1 | F26: 1 | G26: 2 | H26: 2000 | I26: 2100 | L26: Materiales de Administración, Emisión de Documentos y Artículos Oficiales | M26: =+M27+M29+M31+M33+M35 -> 0
B27: 2026 | C27: 21 | D27: 43 | E27: 1 | F27: 1 | G27: 2 | H27: 2000 | I27: 2100 | J27: 211 | L27: Materiales, útiles y equipos menores de oficina | M27: =SUM(M28) -> 0
B28: 2026 | C28: 21 | D28: 43 | E28: 1 | F28: 1 | G28: 2 | H28: 2000 | I28: 2100 | J28: 211 | K28: 915 | L28: Materiales y útiles de oficina | N28: Pieza/Lote
B29: 2026 | C29: 21 | D29: 43 | E29: 1 | F29: 1 | G29: 2 | H29: 2000 | I29: 2100 | J29: 212 | L29: Materiales y útiles de impresión y reproducción | M29: =SUM(M30) -> 0
B30: 2026 | C30: 21 | D30: 43 | E30: 1 | F30: 1 | G30: 2 | H30: 2000 | I30: 2100 | J30: 212 | K30: 914 | L30: Materiales y útiles de impresión y reproducción | N30: Lote
B31: 2026 | C31: 21 | D31: 43 | E31: 1 | F31: 1 | G31: 2 | H31: 2000 | I31: 2100 | J31: 214 | L31: Materiales, útiles y equipos menores de tecnologías de la información y comunicaciones | M31: =SUM(M32) -> 0
B32: 2026 | C32: 21 | D32: 43 | E32: 1 | F32: 1 | G32: 2 | H32: 2000 | I32: 2100 | J32: 214 | K32: 916 | L32: Materiales y útiles para el procesamiento en equipos y bienes informáticos | N32: Lote
B33: 2026 | C33: 21 | D33: 43 | E33: 1 | F33: 1 | G33: 2 | H33: 2000 | I33: 2100 | J33: 216 | L33: Material de limpieza | M33: =SUM(M34) -> 0
B34: 2026 | C34: 21 | D34: 43 | E34: 1 | F34: 1 | G34: 2 | H34: 2000 | I34: 2100 | J34: 216 | K34: 907 | L34: Material de limpieza | N34: Lote
B35: 2026 | C35: 21 | D35: 43 | E35: 1 | F35: 1 | G35: 2 | H35: 2000 | I35: 2100 | J35: 217 | L35: Materiales y útiles de enseñanza | M35: =SUM(M36) -> 0
B36: 2026 | C36: 21 | D36: 43 | E36: 1 | F36: 1 | G36: 2 | H36: 2000 | I36: 2100 | J36: 217 | K36: 913 | L36: Materiales y suministros para planteles educativos | N36: Lote
B37: 2026 | C37: 21 | D37: 43 | E37: 1 | F37: 1 | G37: 2 | H37: 2000 | I37: 2600 | L37: Combustibles, lubricantes y aditivos | M37: =M38 -> 0
B38: 2026 | C38: 21 | D38: 43 | E38: 1 | F38: 1 | G38: 2 | H38: 2000 | I38: 2600 | J38: 261 | L38: Combustibles, lubricantes y aditivos | M38: =M39 -> 0
B39: 2026 | C39: 21 | D39: 43 | E39: 1 | F39: 1 | G39: 2 | H39: 2000 | I39: 2600 | J39: 261 | K39: 700 | L39: Gasolina y diésel | N39: Litro
B40: 2026 | C40: 21 | D40: 43 | E40: 1 | F40: 1 | G40: 2 | H40: 2000 | I40: 2700 | L40: Vestuario, Blancos, Prendas de Protección y Artículos Deportivos | M40: =+M41+M67+M69 -> 0
B41: 2026 | C41: 21 | D41: 43 | E41: 1 | F41: 1 | G41: 2 | H41: 2000 | I41: 2700 | J41: 271 | L41: Vestuario y uniformes | M41: =SUBTOTAL(9,M42:M66) -> 0
...
